<?xml version="1.0"?>
<robot xmlns:xacro="http://www.ros.org/wiki/xacro"  name="robot">

  <xacro:include filename="inertial_macros.xacro" />

  <material name="black">
    <color rgba="0 0 0 1"/>
  </material>

  <material name="white">
    <color rgba="1 1 1 1"/>
  </material>

  <material name="orange">
    <color rgba="1 0.5 0 1"/>
  </material>

  <material name="blue">
    <color rgba="0 0 1 1"/>
  </material>

  <material name="red">
    <color rgba="1 0 0 1"/>
  </material>

  <material name="green">
    <color rgba="0 1 0 1"/>
  </material>

  <!-- BASE LINK -->

  <!-- Set to be the center of the two drive wheels -->
  <link name="base_link">
    
  </link>

  <!-- CHASSIS LINK -->

  <joint name="chassis_joint" type="fixed">
    <parent link="base_link"/>
    <child link="chassis"/>
    <origin xyz="0 0 0.025" />
  </joint>

  <link name="chassis">
    <!-- Cylinder with r=120mm, h=50mm (ASSUMPTION) -->
    <visual>
      <geometry>
        <cylinder length="0.05" radius="0.12"/>
      </geometry>
      <material name="white"/>
    </visual>
    <collision>
      <geometry>
        <cylinder length="0.05" radius="0.12"/>
      </geometry>
    </collision>
    <!-- Mass=0.5kg (ASSUMPTION) -->
    <xacro:inertial_cylinder mass="0.5" length="0.05" radius="0.12">
      <!-- Not sure if this is correct -->
      <origin xyz="0 0 0.025" rpy="0 0 0"/>
    </xacro:inertial_cylinder>
  </link>

  <gazebo reference="chassis">
    <material>Gazebo/White</material>
  </gazebo>

  <!-- LEFT WHEEL LINK -->
  <joint name="left_wheel_joint" type="continuous">
    <parent link="base_link"/>
    <child link="left_wheel"/>
    <origin xyz="0 0.122 0" rpy="-${pi/2} 0 0"/>
    <axis xyz="0 0 1"/>
  </joint>

  <link name="left_wheel">
    <!-- Cylinder with r=30mm, h=8mm (FROM WEBSITE) -->
    <visual>
      <geometry>
        <cylinder length="0.008" radius="0.03"/>
      </geometry>
      <material name="blue"/>
    </visual>
    <collision>
      <geometry>
        <cylinder length="0.008" radius="0.03"/>
      </geometry>
    </collision>
    <!-- Mass=0.1kg (ASSUMPTION) -->
    <xacro:inertial_cylinder mass="0.1" length="0.008" radius="0.03">
      <origin xyz="0 0 0" rpy="0 0 0"/>
    </xacro:inertial_cylinder>
  </link>

  <gazebo reference="left_wheel">
    <material>Gazebo/Blue</material>
  </gazebo>

  <!-- RIGHT WHEEL LINK -->
  <joint name="right_wheel_joint" type="continuous">
    <parent link="base_link"/>
    <child link="right_wheel"/>
    <origin xyz="0 -0.122 0" rpy="${pi/2} 0 0"/>
    <axis xyz="0 0 1"/>
  </joint>

  <link name="right_wheel">
    <!-- Cylinder with r=30mm, h=8mm (FROM WEBSITE) -->
    <visual>
      <geometry>
        <cylinder length="0.008" radius="0.03"/>
      </geometry>
      <material name="blue"/>
    </visual>
    <collision>
      <geometry>
        <cylinder length="0.008" radius="0.03"/>
      </geometry>
    </collision>
    <!-- Mass=0.1kg (ASSUMPTION) -->
    <xacro:inertial_cylinder mass="0.1" length="0.008" radius="0.03">
      <origin xyz="0 0 0" rpy="0 0 0"/>
    </xacro:inertial_cylinder>
  </link>

  <gazebo reference="right_wheel">
    <material>Gazebo/Blue</material>
  </gazebo>

  <!-- CASTER WHEEL LINK -->
  <!-- Frictionless ball that does not rotate -->
  <joint name="caster_wheel_joint" type="fixed">
    <parent link="chassis"/>
    <child link="caster_wheel"/>
    <origin xyz="-0.0875 0 -0.03"/>
  </joint>

  <link name="caster_wheel">
    <!-- Sphere with r=25mm (ASSUMPTION) -->
    <visual>
      <geometry>
        <sphere radius="0.025"/>
      </geometry>
      <material name="red"/>
    </visual>
    <collision>
      <geometry>
        <sphere radius="0.025"/>
      </geometry>
    </collision>
    <!-- Mass=0.1kg (ASSUMPTION) -->
    <xacro:inertial_sphere mass="0.1" radius="0.025">
      <origin xyz="0 0 0" rpy="0 0 0"/>
    </xacro:inertial_sphere>
  </link>

  <!-- No friction -->
  <gazebo reference="caster_wheel">
    <material>Gazebo/Red</material>
    <mu1>0.001</mu1>
    <mu2>0.001</mu2>
  </gazebo>
</robot>
